Workbook

Sheet Summary
A1: NORTHERN FASHION LIMITED
A3: Cutting, Print, Embroidery, Input Production Report ( Month Of September '2026)
A5: Production Date:17.09.26 | G5: Report Date :18.09.2026
A7: AT A GLANCE | B7: SL NO | C7: Buyer Name | D7: Style Qty | E7: Total Ord. Qty | F7: Total Cting .Qty | G7: Total Cting Blance .Qty | H7: Total Inp .Qty | I7: Total Inp Blance.Qty
B8: 1 | C8: Forever New Ching PTY ltd | D8: 2 | E8: 13814 | F8: =#REF! -> #REF! | G8: =F8-E8 -> #REF! | H8: =#REF! -> #REF! | I8: =H8-F8 -> #REF!
B9: 2 | C9: GBX Trading ( Splash ) | D9: 1 | E9: 27930 | F9: =#REF! -> #REF! | G9: =F9-E9 -> #REF! | H9: =#REF! -> #REF! | I9: =H9-F9 -> #REF!
B10: 3 | C10: Best Corporation ( BigW ) | D10: 7 | E10: 35000 | F10: =#REF! -> #REF! | H10: =#REF! -> #REF! | I10: =H10-F10 -> #REF!
B11: 4 | C11: Li & Fung.Lojas Renner | D11: 18 | E11: 224918 | F11: =#REF! -> #REF! | G11: =F11-E11 -> #REF! | H11: =#REF! -> #REF! | I11: =H11-F11 -> #REF!
B12: 5 | C12: GBX Trading ( New Look ) | D12: 21 | E12: 120253 | F12: =#REF! -> #REF! | G12: =F12-E12 -> #REF! | H12: =#REF! -> #REF! | I12: =H12-F12 -> #REF!
B13: 6 | C13: Gruppocion ( + Upim) Grils | D13: 1 | E13: 3060 | F13: =#REF! -> #REF! | G13: =F13-E13 -> #REF! | H13: =#REF! -> #REF! | I13: =H13-F13 -> #REF!
B14: 7 | C14: ( Spa ) Girls | D14: 2 | E14: 40316 | F14: =#REF! -> #REF! | G14: =F14-E14 -> #REF! | H14: =#REF! -> #REF! | I14: =H14-F14 -> #REF!
B15: 8 | C15: Lager 157 AB | D15: 9 | E15: 127207 | F15: =#REF! -> #REF! | G15: =F15-E15 -> #REF! | H15: =#REF! -> #REF! | I15: =H15-F15 -> #REF!
B16: 9 | C16: United Textile Group ( U T G ) ( Zalando) | D16: 55 | E16: 424200 | F16: =#REF! -> #REF! | G16: =F16-E16 -> #REF! | H16: =#REF! -> #REF! | I16: =H16-F16 -> #REF!
B17: 10 | C17: United Textile Group ( U T G ) ( Olet) | D17: 12 | E17: 22000 | F17: =#REF! -> #REF! | G17: =F17-E17 -> #REF! | H17: =#REF! -> #REF! | I17: =H17-F17 -> #REF!
B18: 11 | C18: Best Seller | D18: =5+8+56 -> 69 | E18: =10690+22088+168399 -> 201177 | F18: =#REF! -> #REF! | G18: =F18-E18 -> #REF! | H18: =#REF! -> #REF! | I18: =H18-F18 -> #REF!
B19: G.Total : | D19: =SUM(D8:D18) -> 197 | E19: =SUM(E8:E18) -> 1239875 | F19: =SUM(F8:F18) -> #REF! | G19: =SUM(G8:G18) -> #REF! | H19: =SUM(H8:H18) -> #REF! | I19: =SUM(I8:I18) -> #REF!
D35: Today Cutting | F35: ='Production '!L2258 -> 59025
D36: Month Of September G : Total Cutting | F36: =54864+47515+49192+53263+61506+54059+67005+60402+57638+58219+55736+60606+56662 -> 736667
D37: Month Of September Working Day | F37: 13
D38: Month Of September Avarage Cutting | F38: =F36/F37 -> 56666.692
D39: G: Total Cutting | F39: ='Production '!M2258 -> 2043097
D40: G.total W.I.P. | F40: ='Production '!X2258 -> -537967
D41: Today Inp (Sewing) | F41: ='Production '!V2258 -> 43847
D42: G.Total Inp (Sewing) | F42: ='Production '!W2258 -> 1505130
D43: Worker Present
D44: Staff Present | F44: 35
A54: Prepared By | D54: Ct : Officer / Incharg | H54: Cting Manager

Sheet Production 
B1: NORTHERN FASHION LIMITTED
B2: Buyer & Style Wise Daily Cutting, Input & Print Production Summary
B3: Production Date: | D3: 17.09.26 | V3: Report Date : | X3: 18.09.26
B4: Buyer Name | C4: Job No | D4: Style | E4: Color | F4: Ord . Qty | G4: T& A Plan ( Deying ) | H4: Cutting T & A Plan | J4: Sewing Floor | K4: Ship Date | L4: Today Cutting | M4: Total Cutting | N4: Cutting Balance | O4: First Print Sent Date | P4: Today Print Sent | Q4: Total Print Send | R4: Today Print Rcvd | S4: Total Print Recv | T4: Print Balance | U4: Total Ready for Input | V4: Today Input | W4: Total Inp | X4: Inp Balance | Y4: Print/Emb | Z4: Factory Name | AA4: Schedule Close Date | AB4: Remarks | AC4: Reason of short | AD4: Present status | AE4: Cut Bal % | AG4: Cut Bal | AH4: Print Rcv short | AI4: Inout short
H5: Start | I5: End
B6: -New Look | C6: 48553 | D6: 9686355 | E6: 41 Navy | F6: 890 | N6: =M6-F6 -> -890 | T6: =S6-Q6 -> 0 | U6: =IF(Q6>0,S6-W6,M6-W6) -> 0 | X6: =W6-M6 -> 0 | AE6: =N6/F6 -> -1 | AG6: =IF(N6<0,N6,0) -> -890 | AH6: =(S6-F6)/F6 -> -1 | AI6: =(W6-F6)/F6 -> -1
B7: -New Look | C7: 48553 | E7: 4 Mid Grey | F7: 1110 | N7: =M7-F7 -> -1110 | T7: =S7-Q7 -> 0 | U7: =IF(Q7>0,S7-W7,M7-W7) -> 0 | X7: =W7-M7 -> 0 | AE7: =N7/F7 -> -1 | AG7: =IF(N7<0,N7,0) -> -1110 | AH7: =(S7-F7)/F7 -> -1 | AI7: =(W7-F7)/F7 -> -1
A8: Sub Total | B8: -New Look | F8: =SUM(F6:F7) -> 2000 | J8: S3 | K8: 26.09.26 | L8: =SUM(L6:L7) -> 0 | M8: =SUM(M6:M7) -> 0 | N8: =SUM(N6:N7) -> -2000 | P8: =SUM(P6:P7) -> 0 | Q8: =SUM(Q6:Q7) -> 0 | R8: =SUM(R6:R7) -> 0 | S8: =SUM(S6:S7) -> 0 | T8: =SUM(T6:T7) -> 0 | U8: =SUM(U6:U7) -> 0 | V8: =SUM(V6:V7) -> 0 | W8: =SUM(W6:W7) -> 0 | X8: =SUM(X6:X7) -> 0 | AE8: =N8/F8 -> -1 | AG8: =IF(N8<0,N8,0) -> -2000 | AH8: =(S8-F8)/F8 -> -1 | AI8: =(W8-F8)/F8 -> -1
B9: -New Look | C9: 48551 1st | D9: 9686529 | E9: Pink Pattern | F9: 5350 | N9: =M9-F9 -> -5350 | T9: =S9-Q9 -> 0 | U9: =IF(Q9>0,S9-W9,M9-W9) -> 0 | X9: =W9-M9 -> 0 | AE9: =N9/F9 -> -1 | AG9: =IF(N9<0,N9,0) -> -5350 | AH9: =(S9-F9)/F9 -> -1 | AI9: =(W9-F9)/F9 -> -1
A10: Sub Total | B10: -New Look | F10: =SUM(F9:F9) -> 5350 | J10: S3 | K10: 26.09.26 | L10: =SUM(L9:L9) -> 0 | M10: =SUM(M9:M9) -> 0 | N10: =SUM(N9:N9) -> -5350 | P10: =SUM(P9:P9) -> 0 | Q10: =SUM(Q9:Q9) -> 0 | R10: =SUM(R9:R9) -> 0 | S10: =SUM(S9:S9) -> 0 | T10: =SUM(T9:T9) -> 0 | U10: =SUM(U9:U9) -> 0 | V10: =SUM(V9:V9) -> 0 | W10: =SUM(W9:W9) -> 0 | X10: =SUM(X9:X9) -> 0 | Y10: P | Z10: NFL | AE10: =N10/F10 -> -1 | AG10: =IF(N10<0,N10,0) -> -5350 | AH10: =(S10-F10)/F10 -> -1 | AI10: =(W10-F10)/F10 -> -1
B11: G.Total (GBX New Look) >>> | F11: =+F10+F8 -> 7350 | L11: =+L10+L8 -> 0 | M11: =+M10+M8 -> 0 | N11: =+N10+N8 -> -7350 | P11: =+P10+P8 -> 0 | Q11: =+Q10+Q8 -> 0 | R11: =+R10+R8 -> 0 | S11: =+S10+S8 -> 0 | T11: =+T10+T8 -> 0 | U11: =+U10+U8 -> 0 | V11: =+V10+V8 -> 0 | W11: =+W10+W8 -> 0 | X11: =+X10+X8 -> 0 | AE11: =N11/F11 -> -1 | AG11: =IF(N11<0,N11,0) -> -7350 | AH11: =(S11-F11)/F11 -> -1 | AI11: =(W11-F11)/F11 -> -1
B12: Guess | C12: 46594 | D12: Q6VPA6K6618 | E12: Luxe Pink | F12: 2310 | M12: =1032+924+456 -> 2412 | N12: =M12-F12 -> 102 | T12: =S12-Q12 -> 0 | U12: =IF(Q12>0,S12-W12,M12-W12) -> 55 | W12: =1005+1352 -> 2357 | X12: =+W12-M12 -> -55 | AE12: =N12/F12 -> 0.044155844 | AG12: =IF(N12<0,N12,0) -> 0 | AH12: =(S12-F12)/F12 -> -1 | AI12: =(W12-F12)/F12 -> 0.02034632
B13: Guess | C13: 46594 | E13: Jet Black | F13: 2712 | M13: =480+432+246+924+669 -> 2751 | N13: =M13-F13 -> 39 | T13: =S13-Q13 -> 0 | U13: =IF(Q13>0,S13-W13,M13-W13) -> 12 | W13: =2271+468 -> 2739 | X13: =+W13-M13 -> -12 | AE13: =N13/F13 -> 0.014380531 | AG13: =IF(N13<0,N13,0) -> 0 | AH13: =(S13-F13)/F13 -> -1 | AI13: =(W13-F13)/F13 -> 0.0099557522
B14: Guess | C14: 46594 | E14: Pure White | F14: 2200 | M14: =432+1032+804+36 -> 2304 | N14: =M14-F14 -> 104 | T14: =S14-Q14 -> 0 | U14: =IF(Q14>0,S14-W14,M14-W14) -> 0 | W14: 2304 | X14: =+W14-M14 -> 0 | AE14: =N14/F14 -> 0.047272727 | AG14: =IF(N14<0,N14,0) -> 0 | AH14: =(S14-F14)/F14 -> -1 | AI14: =(W14-F14)/F14 -> 0.047272727
B15: Guess | C15: 46594 | E15: Peasley Beige | F15: 1900 | M15: =708+1260 -> 1968 | N15: =M15-F15 -> 68 | T15: =S15-Q15 -> 0 | U15: =IF(Q15>0,S15-W15,M15-W15) -> 0 | W15: 1968 | X15: =+W15-M15 -> 0 | AE15: =N15/F15 -> 0.035789474 | AG15: =IF(N15<0,N15,0) -> 0 | AH15: =(S15-F15)/F15 -> -1 | AI15: =(W15-F15)/F15 -> 0.035789474
A16: Sub Total | B16: Guess | F16: =SUM(F12:F15) -> 9122 | J16: S1 | K16: 09.03.26 | L16: =SUM(L12:L15) -> 0 | M16: =SUM(M12:M15) -> 9435 | N16: =SUM(N12:N15) -> 313 | P16: =SUM(P12:P15) -> 0 | Q16: =SUM(Q12:Q15) -> 0 | R16: =SUM(R12:R15) -> 0 | S16: =SUM(S12:S15) -> 0 | T16: =SUM(T12:T15) -> 0 | U16: =IF(Q16>0,S16-W16,M16-W16) -> 67 | V16: =SUM(V12:V15) -> 0 | W16: =SUM(W12:W15) -> 9368 | X16: =SUM(X12:X15) -> -67 | AE16: =N16/F16 -> 0.034312651 | AG16: =IF(N16<0,N16,0) -> 0 | AH16: =(S16-F16)/F16 -> -1 | AI16: =(W16-F16)/F16 -> 0.02696777
B17: G.Total (GBX New Look) >>> | F17: =+F16 -> 9122 | L17: =+L16 -> 0 | M17: =+M16 -> 9435 | N17: =+N16 -> 313 | P17: =+P16 -> 0 | Q17: =+Q16 -> 0 | R17: =+R16 -> 0 | S17: =+S16 -> 0 | T17: =+T16 -> 0 | U17: =IF(Q17>0,S17-W17,M17-W17) -> 67 | V17: =+V16 -> 0 | W17: =+W16 -> 9368 | X17: =+X16 -> -67 | AE17: =N17/F17 -> 0.034312651 | AG17: =IF(N17<0,N17,0) -> 0 | AH17: =(S17-F17)/F17 -> -1 | AI17: =(W17-F17)/F17 -> 0.02696777
B18: Sainsbury's | C18: 47437 | D18: 148278404 | E18: Red | F18: 15144 | M18: =504+1272+1456+800+480+624+1688+1816+1480+704+1288+1328+408+1671 -> 15519 | N18: =M18-F18 -> 375 | Q18: =504+960+1272+800+1104+480+1621+1336+496+536+456+488+1288+1112+1328+1671+67 -> 15519 | S18: =18+844+1042+1125+1024+1088+1045+939+1098+751+1052+1133+978+1010+1060+1312 -> 15519 | T18: =S18-Q18 -> 0 | U18: =IF(Q18>0,S18-W18,M18-W18) -> 75 | W18: =1196+1159+1527+429+832+752+2805+1364+2315+2339+726 -> 15444 | X18: =+W18-M18 -> -75 | AE18: =N18/F18 -> 0.024762282 | AG18: =IF(N18<0,N18,0) -> 0 | AH18: =(S18-F18)/F18 -> 0.024762282 | AI18: =(W18-F18)/F18 -> 0.019809826
A19: Sub Total | B19: Sainsbury's | F19: =SUM(F18:F18) -> 15144 | J19: S3 | K19: 27.06.26 | L19: =SUM(L18:L18) -> 0 | M19: =SUM(M18:M18) -> 15519 | N19: =SUM(N18:N18) -> 375 | O19: 16.06.26 | P19: =SUM(P18:P18) -> 0 | Q19: =SUM(Q18:Q18) -> 15519 | R19: =SUM(R18:R18) -> 0 | S19: =SUM(S18:S18) -> 15519 | T19: =SUM(T18:T18) -> 0 | U19: =IF(Q19>0,S19-W19,M19-W19) -> 75 | V19: =SUM(V18:V18) -> 0 | W19: =SUM(W18:W18) -> 15444 | X19: =SUM(X18:X18) -> -75 | Y19: P+E | Z19: NFL | AE19: =N19/F19 -> 0.024762282 | AG19: =IF(N19<0,N19,0) -> 0 | AH19: =(S19-F19)/F19 -> 0.024762282 | AI19: =(W19-F19)/F19 -> 0.019809826
B20: G.Total (GBX Sainsburys >>> | F20: =+F19 -> 15144 | L20: =+L19 -> 0 | M20: =+M19 -> 15519 | N20: =+N19 -> 375 | P20: =+P19 -> 0 | Q20: =+Q19 -> 15519 | R20: =+R19 -> 0 | S20: =+S19 -> 15519 | T20: =+T19 -> 0 | U20: =IF(Q20>0,S20-W20,M20-W20) -> 75 | V20: =+V19 -> 0 | W20: =+W19 -> 15444 | X20: =+X19 -> -75 | AE20: =N20/F20 -> 0.024762282 | AG20: =IF(N20<0,N20,0) -> 0 | AH20: =(S20-F20)/F20 -> 0.024762282 | AI20: =(W20-F20)/F20 -> 0.019809826
B21: Maurices | C21: 48245 2nd | D21: 2524991/4704991 | E21: White+Black y/d | F21: 5346 | M21: =432+300+584+616+528+600+538+252+826+670 -> 5346 | N21: =M21-F21 -> 0 | T21: =S21-Q21 -> 0 | U21: =IF(Q21>0,S21-W21,M21-W21) -> 75 | W21: 5271 | X21: =+W21-M21 -> -75 | AE21: =N21/F21 -> 0 | AG21: =IF(N21<0,N21,0) -> 0 | AH21: =(S21-F21)/F21 -> -1 | AI21: =(W21-F21)/F21 -> -0.014029181
B22: Maurices | C22: 48245 2nd | E22: Twilight Mave y/d | F22: 7028 | M22: =348+408+688+2404+1220+540+500+920 -> 7028 | N22: =M22-F22 -> 0 | T22: =S22-Q22 -> 0 | U22: =IF(Q22>0,S22-W22,M22-W22) -> 200 | W22: =1341+2359+3128 -> 6828 | X22: =+W22-M22 -> -200 | AE22: =N22/F22 -> 0 | AG22: =IF(N22<0,N22,0) -> 0 | AH22: =(S22-F22)/F22 -> -1 | AI22: =(W22-F22)/F22 -> -0.028457598
A23: Sub Total | B23: Maurices | F23: =SUM(F21:F22) -> 12374 | I23: NC | J23: S3 | K23: 25.08.26 | L23: =SUM(L21:L22) -> 0 | M23: =SUM(M21:M22) -> 12374 | N23: =SUM(N21:N22) -> 0 | P23: =SUM(P21:P22) -> 0 | Q23: =SUM(Q21:Q22) -> 0 | R23: =SUM(R21:R22) -> 0 | S23: =SUM(S21:S22) -> 0 | T23: =SUM(T21:T22) -> 0 | U23: =SUM(U21:U22) -> 275 | V23: =SUM(V21:V22) -> 0 | W23: =SUM(W21:W22) -> 12099 | X23: =SUM(X21:X22) -> -275 | AE23: =N23/F23 -> 0 | AG23: =IF(N23<0,N23,0) -> 0 | AH23: =(S23-F23)/F23 -> -1 | AI23: =(W23-F23)/F23 -> -0.022224018
B24: Left Over | C24: Left Over | E24: Dark Sapphire | F24: 408 | M24: =408 -> 408 | N24: =M24-F24 -> 0 | T24: =S24-Q24 -> 0 | U24: =IF(Q24>0,S24-W24,M24-W24) -> 25 | W24: 383 | X24: =+W24-M24 -> -25 | AE24: =N24/F24 -> 0 | AG24: =IF(N24<0,N24,0) -> 0 | AH24: =(S24-F24)/F24 -> -1 | AI24: =(W24-F24)/F24 -> -0.06127451
A25: Sub Total | B25: Left Over | F25: =SUM(F24:F24) -> 408 | J25: S3 | L25: =SUM(L24:L24) -> 0 | M25: =SUM(M24:M24) -> 408 | N25: =SUM(N24:N24) -> 0 | P25: =SUM(P24:P24) -> 0 | Q25: =SUM(Q24:Q24) -> 0 | R25: =SUM(R24:R24) -> 0 | S25: =SUM(S24:S24) -> 0 | T25: =SUM(T24:T24) -> 0 | U25: =IF(Q25>0,S25-W25,M25-W25) -> 25 | V25: =SUM(V24:V24) -> 0 | W25: =SUM(W24:W24) -> 383 | X25: =SUM(X24:X24) -> -25 | AE25: =N25/F25 -> 0 | AG25: =IF(N25<0,N25,0) -> 0 | AH25: =(S25-F25)/F25 -> -1 | AI25: =(W25-F25)/F25 -> -0.06127451
B26: BS-NMT | C26: 43319 21th | D26: 13238718 | E26: Black+White y/d-Top | F26: =440+840 -> 1280 | M26: =440+840 -> 1280 | N26: =M26-F26 -> 0 | Q26: =425+821+10+11 -> 1267 | S26: =1256+11 -> 1267 | T26: =S26-Q26 -> 0 | U26: =IF(Q26>0,S26-W26,M26-W26) -> 0 | W26: 1267 | X26: =+W26-M26 -> -13 | AE26: =N26/F26 -> 0 | AG26: =IF(N26<0,N26,0) -> 0 | AH26: =(S26-F26)/F26 -> -0.01015625 | AI26: =(W26-F26)/F26 -> -0.01015625
B27: BS-NMT | C27: 43319 21th | E27: Evening Blue-Top | F27: 2238 | M27: =742+1400+96 -> 2238 | N27: =M27-F27 -> 0 | Q27: =742+1400+96 -> 2238 | S27: 2235 | T27: =S27-Q27 -> -3 | U27: =IF(Q27>0,S27-W27,M27-W27) -> 1 | W27: 2234 | X27: =+W27-M27 -> -4 | AE27: =N27/F27 -> 0 | AG27: =IF(N27<0,N27,0) -> 0 | AH27: =(S27-F27)/F27 -> -0.0013404826 | AI27: =(W27-F27)/F27 -> -0.0017873101
B28: BS-NMT | C28: 43319 21th | E28: Cloud Dancer-Top | F28: 600 | M28: 600 | N28: =M28-F28 -> 0 | Q28: =600 -> 600 | S28: =583 -> 583 | T28: =S28-Q28 -> -17 | U28: =IF(Q28>0,S28-W28,M28-W28) -> 583 | X28: =+W28-M28 -> -600 | AE28: =N28/F28 -> 0 | AG28: =IF(N28<0,N28,0) -> 0 | AH28: =(S28-F28)/F28 -> -0.028333333 | AI28: =(W28-F28)/F28 -> -1
A29: Sub Total | B29: Left Over | F29: =SUM(F26:F28) -> 4118 | J29: S3 | L29: =SUM(L26:L28) -> 0 | M29: =SUM(M26:M28) -> 4118 | N29: =SUM(N26:N28) -> 0 | O29: 26.08.26 | P29: =SUM(P26:P28) -> 0 | Q29: =SUM(Q26:Q28) -> 4105 | R29: =SUM(R26:R28) -> 0 | S29: =SUM(S26:S28) -> 4085 | T29: =SUM(T26:T28) -> -20 | U29: =SUM(U26:U28) -> 584 | V29: =SUM(V26:V28) -> 0 | W29: =SUM(W26:W28) -> 3501 | X29: =SUM(X26:X28) -> -617 | Y29: P | Z29: NFL | AE29: =N29/F29 -> 0 | AG29: =IF(N29<0,N29,0) -> 0 | AH29: =(S29-F29)/F29 -> -0.0080135988 | AI29: =(W29-F29)/F29 -> -0.14983001
B30: BS-NMT | C30: 41831 8th | D30: 13239415 | E30: Black+White y/d-Pant | F30: 8434 | M30: =2238+976+1620+476+748+436+340+1600 -> 8434 | N30: =M30-F30 -> 0 | Q30: =2238+968+1610+476+1157+1585 -> 8034 | S30: =2208+3048+1155+1583 -> 7994 | T30: =S30-Q30 -> -40 | U30: =IF(Q30>0,S30-W30,M30-W30) -> 2742 | W30: =5252 -> 5252 | X30: =+W30-M30 -> -3182 | AE30: =N30/F30 -> 0 | AG30: =IF(N30<0,N30,0) -> 0 | AH30: =(S30-F30)/F30 -> -0.052169789 | AI30: =(W30-F30)/F30 -> -0.37728243
B31: BS-NMT | C31: 41831 8th | E31: Black-Pant | F31: 2496 | M31: 2496 | N31: =M31-F31 -> 0 | Q31: 2454 | S31: 2451 | T31: =S31-Q31 -> -3 | U31: =IF(Q31>0,S31-W31,M31-W31) -> 10 | W31: 2441 | X31: =+W31-M31 -> -55 | AE31: =N31/F31 -> 0 | AG31: =IF(N31<0,N31,0) -> 0 | AH31: =(S31-F31)/F31 -> -0.018028846 | AI31: =(W31-F31)/F31 -> -0.022035256
B32: BS-NMT | C32: 41831 8th | E32: Cloud Dancer-Pant | F32: 816 | M32: 816 | N32: =M32-F32 -> 0 | Q32: =256+530 -> 786 | S32: =256+528 -> 784 | T32: =S32-Q32 -> -2 | U32: =IF(Q32>0,S32-W32,M32-W32) -> 784 | X32: =+W32-M32 -> -816 | AE32: =N32/F32 -> 0 | AG32: =IF(N32<0,N32,0) -> 0 | AH32: =(S32-F32)/F32 -> -0.039215686 | AI32: =(W32-F32)/F32 -> -1
B33: BS-NMT | C33: 41831 8th | E33: Red-Pant | F33: 2888 | M33: =1576+500+812 -> 2888 | N33: =M33-F33 -> 0 | Q33: =1576+796+294 -> 2666 | S33: =1870+796 -> 2666 | T33: =S33-Q33 -> 0 | U33: =IF(Q33>0,S33-W33,M33-W33) -> 2666 | X33: =+W33-M33 -> -2888 | AE33: =N33/F33 -> 0 | AG33: =IF(N33<0,N33,0) -> 0 | AH33: =(S33-F33)/F33 -> -0.076869806 | AI33: =(W33-F33)/F33 -> -1
A34: Sub Total | B34: Left Over | F34: =SUM(F30:F33) -> 14634 | J34: S3 | L34: =SUM(L30:L33) -> 0 | M34: =SUM(M30:M33) -> 14634 | N34: =SUM(N30:N33) -> 0 | O34: 27.08.26 | P34: =SUM(P30:P33) -> 0 | Q34: =SUM(Q30:Q33) -> 13940 | R34: =SUM(R30:R33) -> 0 | S34: =SUM(S30:S33) -> 13895 | T34: =SUM(T30:T33) -> -45 | U34: =SUM(U30:U33) -> 6202 | V34: =SUM(V30:V33) -> 0 | W34: =SUM(W30:W33) -> 7693 | X34: =SUM(X30:X33) -> -6941 | Y34: P | Z34: NFL | AE34: =N34/F34 -> 0 | AG34: =IF(N34<0,N34,0) -> 0 | AH34: =(S34-F34)/F34 -> -0.050498838 | AI34: =(W34-F34)/F34 -> -0.47430641
B35: G.Total (GBX Maurice >>> | F35: =+F34+F23+F29+F25 -> 31534 | L35: =+L34+L23+L29+L25 -> 0 | M35: =+M34+M23+M29+M25 -> 31534 | N35: =+N34+N23+N29+N25 -> 0 | P35: =+P34+P23+P29+P25 -> 0 | Q35: =+Q34+Q23+Q29+Q25 -> 18045 | R35: =+R34+R23+R29+R25 -> 0 | S35: =+S34+S23+S29+S25 -> 17980 | T35: =+T34+T23+T29+T25 -> -65 | U35: =+U34+U23+U29+U25 -> 7086 | V35: =+V34+V23+V29+V25 -> 0 | W35: =+W34+W23+W29+W25 -> 23676 | X35: =+X34+X23+X29+X25 -> -7858 | AE35: =N35/F35 -> 0 | AG35: =IF(N35<0,N35,0) -> 0 | AH35: =(S35-F35)/F35 -> -0.42982178 | AI35: =(W35-F35)/F35 -> -0.24919135
B36: T.M Lewin | C36: 47721 | D36: 68663/68664/68665 | E36: Black | F36: 635 | M36: 656 | N36: =M36-F36 -> 21 | T36: =S36-Q36 -> 0 | U36: =IF(Q36>0,S36-W36,M36-W36) -> 9 | W36: 647 | X36: =+W36-M36 -> -9 | AE36: =N36/F36 -> 0.033070866 | AG36: =IF(N36<0,N36,0) -> 0 | AH36: =(S36-F36)/F36 -> -1 | AI36: =(W36-F36)/F36 -> 0.018897638
B37: T.M Lewin | C37: 47721 | E37: Pumice Stone | F37: 425 | M37: =366+78 -> 444 | N37: =M37-F37 -> 19 | T37: =S37-Q37 -> 0 | U37: =IF(Q37>0,S37-W37,M37-W37) -> 5 | W37: 439 | X37: =+W37-M37 -> -5 | AE37: =N37/F37 -> 0.044705882 | AG37: =IF(N37<0,N37,0) -> 0 | AH37: =(S37-F37)/F37 -> -1 | AI37: =(W37-F37)/F37 -> 0.032941176
B38: T.M Lewin | C38: 47721 | E38: Grey Marl | F38: 530 | M38: =228+228+96 -> 552 | N38: =M38-F38 -> 22 | T38: =S38-Q38 -> 0 | U38: =IF(Q38>0,S38-W38,M38-W38) -> 0 | W38: 552 | X38: =+W38-M38 -> 0 | AE38: =N38/F38 -> 0.041509434 | AG38: =IF(N38<0,N38,0) -> 0 | AH38: =(S38-F38)/F38 -> -1 | AI38: =(W38-F38)/F38 -> 0.041509434
A39: Sub Total | B39: T.M Lewin | F39: =SUM(F36:F38) -> 1590 | J39: S2 | K39: 10.08.26 | L39: =SUM(L36:L38) -> 0 | M39: =SUM(M36:M38) -> 1652 | N39: =SUM(N36:N38) -> 62 | P39: =SUM(P36:P38) -> 0 | Q39: =SUM(Q36:Q38) -> 0 | R39: =SUM(R36:R38) -> 0 | S39: =SUM(S36:S38) -> 0 | T39: =SUM(T36:T38) -> 0 | U39: =IF(Q39>0,S39-W39,M39-W39) -> 14 | V39: =SUM(V36:V38) -> 0 | W39: =SUM(W36:W38) -> 1638 | X39: =SUM(X36:X38) -> -14 | AE39: =N39/F39 -> 0.038993711 | AG39: =IF(N39<0,N39,0) -> 0 | AH39: =(S39-F39)/F39 -> -1 | AI39: =(W39-F39)/F39 -> 0.030188679
B40: T.M Lewin | C40: 47425 | D40: 68592 | E40: Black | F40: =1080+528 -> 1608 | M40: =1080+528 -> 1608 | N40: =M40-F40 -> 0 | Q40: =1080+528 -> 1608 | S40: =210+331+534+526 -> 1601 | T40: =S40-Q40 -> -7 | U40: =IF(Q40>0,S40-W40,M40-W40) -> 7 | W40: =1075+519 -> 1594 | X40: =+W40-M40 -> -14 | AE40: =N40/F40 -> 0 | AG40: =IF(N40<0,N40,0) -> 0 | AH40: =(S40-F40)/F40 -> -0.0043532338 | AI40: =(W40-F40)/F40 -> -0.0087064677
...

Sheet Tracking Sheet
B2: Job NO: | C2: Cutting Qty | D2: Print Sent | E2: Print Recv | F2: Ready for input | G2: Sewing Input | H2: Order Qty | I2: Today Input | J2: Cut Bal
B3: ='Production '!C6 -> 48553 | C3: =SUMIF('Production '!$C$4:$AI$4407,'Tracking Sheet'!B3,'Production '!$M$4:$M$4407) -> 0 | D3: =SUMIF('Production '!$C$4:$AI$4407,'Tracking Sheet'!B3,'Production '!$Q$4:$Q$4407) -> 0 | E3: =SUMIF('Production '!$C$4:$AI$4407,'Tracking Sheet'!B3,'Production '!$S$4:$S$4407) -> 0 | F3: =SUMIF('Production '!$C$4:$AI$4407,'Tracking Sheet'!B3,'Production '!$U$4:$U$4407) -> 0 | G3: =SUMIF('Production '!$C$4:$AI$4407,'Tracking Sheet'!B3,'Production '!$W$4:$W$4407) -> 0 | H3: =SUMIF('Production '!$C$4:$AI$4407,'Tracking Sheet'!B3,'Production '!$F$4:$F$4407) -> 2000 | I3: =SUMIF('Production '!$C$4:$AI$4407,'Tracking Sheet'!B3,'Production '!$V$4:$V$4407) -> 0 | J3: =SUMIF('Production '!$C$4:$AI$4407,'Tracking Sheet'!B3,'Production '!$AG$4:$AG$4407) -> -2000
B4: ='Production '!C7 -> 48553 | C4: =SUMIF('Production '!$C$4:$AI$4407,'Tracking Sheet'!B4,'Production '!$M$4:$M$4407) -> 0 | D4: =SUMIF('Production '!$C$4:$AI$4407,'Tracking Sheet'!B4,'Production '!$Q$4:$Q$4407) -> 0 | E4: =SUMIF('Production '!$C$4:$AI$4407,'Tracking Sheet'!B4,'Production '!$S$4:$S$4407) -> 0 | F4: =SUMIF('Production '!$C$4:$AI$4407,'Tracking Sheet'!B4,'Production '!$U$4:$U$4407) -> 0 | G4: =SUMIF('Production '!$C$4:$AI$4407,'Tracking Sheet'!B4,'Production '!$W$4:$W$4407) -> 0 | H4: =SUMIF('Production '!$C$4:$AI$4407,'Tracking Sheet'!B4,'Production '!$F$4:$F$4407) -> 2000 | I4: =SUMIF('Production '!$C$4:$AI$4407,'Tracking Sheet'!B4,'Production '!$V$4:$V$4407) -> 0 | J4: =SUMIF('Production '!$C$4:$AI$4407,'Tracking Sheet'!B4,'Production '!$AG$4:$AG$4407) -> -2000
B5: ='Production '!C8 -> 0 | C5: =SUMIF('Production '!$C$4:$AI$4407,'Tracking Sheet'!B5,'Production '!$M$4:$M$4407) -> #DIV/0! | D5: =SUMIF('Production '!$C$4:$AI$4407,'Tracking Sheet'!B5,'Production '!$Q$4:$Q$4407) -> #DIV/0! | E5: =SUMIF('Production '!$C$4:$AI$4407,'Tracking Sheet'!B5,'Production '!$S$4:$S$4407) -> -1268219 | F5: =SUMIF('Production '!$C$4:$AI$4407,'Tracking Sheet'!B5,'Production '!$U$4:$U$4407) -> -10620.436 | G5: =SUMIF('Production '!$C$4:$AI$4407,'Tracking Sheet'!B5,'Production '!$W$4:$W$4407) -> #DIV/0! | H5: =SUMIF('Production '!$C$4:$AI$4407,'Tracking Sheet'!B5,'Production '!$F$4:$F$4407) -> 3230621.3 | I5: =SUMIF('Production '!$C$4:$AI$4407,'Tracking Sheet'!B5,'Production '!$V$4:$V$4407) -> -489.86488 | J5: =SUMIF('Production '!$C$4:$AI$4407,'Tracking Sheet'!B5,'Production '!$AG$4:$AG$4407) -> 0
B6: ='Production '!C9 -> 48551 1st | C6: =SUMIF('Production '!$C$4:$AI$4407,'Tracking Sheet'!B6,'Production '!$M$4:$M$4407) -> 0 | D6: =SUMIF('Production '!$C$4:$AI$4407,'Tracking Sheet'!B6,'Production '!$Q$4:$Q$4407) -> 0 | E6: =SUMIF('Production '!$C$4:$AI$4407,'Tracking Sheet'!B6,'Production '!$S$4:$S$4407) -> 0 | F6: =SUMIF('Production '!$C$4:$AI$4407,'Tracking Sheet'!B6,'Production '!$U$4:$U$4407) -> 0 | G6: =SUMIF('Production '!$C$4:$AI$4407,'Tracking Sheet'!B6,'Production '!$W$4:$W$4407) -> 0 | H6: =SUMIF('Production '!$C$4:$AI$4407,'Tracking Sheet'!B6,'Production '!$F$4:$F$4407) -> 5350 | I6: =SUMIF('Production '!$C$4:$AI$4407,'Tracking Sheet'!B6,'Production '!$V$4:$V$4407) -> 0 | J6: =SUMIF('Production '!$C$4:$AI$4407,'Tracking Sheet'!B6,'Production '!$AG$4:$AG$4407) -> -5350
B7: ='Production '!C10 -> 0 | C7: =SUMIF('Production '!$C$4:$AI$4407,'Tracking Sheet'!B7,'Production '!$M$4:$M$4407) -> #DIV/0! | D7: =SUMIF('Production '!$C$4:$AI$4407,'Tracking Sheet'!B7,'Production '!$Q$4:$Q$4407) -> #DIV/0! | E7: =SUMIF('Production '!$C$4:$AI$4407,'Tracking Sheet'!B7,'Production '!$S$4:$S$4407) -> -1268219 | F7: =SUMIF('Production '!$C$4:$AI$4407,'Tracking Sheet'!B7,'Production '!$U$4:$U$4407) -> -10620.436 | G7: =SUMIF('Production '!$C$4:$AI$4407,'Tracking Sheet'!B7,'Production '!$W$4:$W$4407) -> #DIV/0! | H7: =SUMIF('Production '!$C$4:$AI$4407,'Tracking Sheet'!B7,'Production '!$F$4:$F$4407) -> 3230621.3 | I7: =SUMIF('Production '!$C$4:$AI$4407,'Tracking Sheet'!B7,'Production '!$V$4:$V$4407) -> -489.86488 | J7: =SUMIF('Production '!$C$4:$AI$4407,'Tracking Sheet'!B7,'Production '!$AG$4:$AG$4407) -> 0
B8: ='Production '!C11 -> 0 | C8: =SUMIF('Production '!$C$4:$AI$4407,'Tracking Sheet'!B8,'Production '!$M$4:$M$4407) -> #DIV/0! | D8: =SUMIF('Production '!$C$4:$AI$4407,'Tracking Sheet'!B8,'Production '!$Q$4:$Q$4407) -> #DIV/0! | E8: =SUMIF('Production '!$C$4:$AI$4407,'Tracking Sheet'!B8,'Production '!$S$4:$S$4407) -> -1268219 | F8: =SUMIF('Production '!$C$4:$AI$4407,'Tracking Sheet'!B8,'Production '!$U$4:$U$4407) -> -10620.436 | G8: =SUMIF('Production '!$C$4:$AI$4407,'Tracking Sheet'!B8,'Production '!$W$4:$W$4407) -> #DIV/0! | H8: =SUMIF('Production '!$C$4:$AI$4407,'Tracking Sheet'!B8,'Production '!$F$4:$F$4407) -> 3230621.3 | I8: =SUMIF('Production '!$C$4:$AI$4407,'Tracking Sheet'!B8,'Production '!$V$4:$V$4407) -> -489.86488 | J8: =SUMIF('Production '!$C$4:$AI$4407,'Tracking Sheet'!B8,'Production '!$AG$4:$AG$4407) -> 0
B9: ='Production '!C12 -> 46594 | C9: =SUMIF('Production '!$C$4:$AI$4407,'Tracking Sheet'!B9,'Production '!$M$4:$M$4407) -> 9435 | D9: =SUMIF('Production '!$C$4:$AI$4407,'Tracking Sheet'!B9,'Production '!$Q$4:$Q$4407) -> 0 | E9: =SUMIF('Production '!$C$4:$AI$4407,'Tracking Sheet'!B9,'Production '!$S$4:$S$4407) -> 0 | F9: =SUMIF('Production '!$C$4:$AI$4407,'Tracking Sheet'!B9,'Production '!$U$4:$U$4407) -> 67 | G9: =SUMIF('Production '!$C$4:$AI$4407,'Tracking Sheet'!B9,'Production '!$W$4:$W$4407) -> 9368 | H9: =SUMIF('Production '!$C$4:$AI$4407,'Tracking Sheet'!B9,'Production '!$F$4:$F$4407) -> 9122 | I9: =SUMIF('Production '!$C$4:$AI$4407,'Tracking Sheet'!B9,'Production '!$V$4:$V$4407) -> 0 | J9: =SUMIF('Production '!$C$4:$AI$4407,'Tracking Sheet'!B9,'Production '!$AG$4:$AG$4407) -> 0
B10: ='Production '!C13 -> 46594 | C10: =SUMIF('Production '!$C$4:$AI$4407,'Tracking Sheet'!B10,'Production '!$M$4:$M$4407) -> 9435 | D10: =SUMIF('Production '!$C$4:$AI$4407,'Tracking Sheet'!B10,'Production '!$Q$4:$Q$4407) -> 0 | E10: =SUMIF('Production '!$C$4:$AI$4407,'Tracking Sheet'!B10,'Production '!$S$4:$S$4407) -> 0 | F10: =SUMIF('Production '!$C$4:$AI$4407,'Tracking Sheet'!B10,'Production '!$U$4:$U$4407) -> 67 | G10: =SUMIF('Production '!$C$4:$AI$4407,'Tracking Sheet'!B10,'Production '!$W$4:$W$4407) -> 9368 | H10: =SUMIF('Production '!$C$4:$AI$4407,'Tracking Sheet'!B10,'Production '!$F$4:$F$4407) -> 9122 | I10: =SUMIF('Production '!$C$4:$AI$4407,'Tracking Sheet'!B10,'Production '!$V$4:$V$4407) -> 0 | J10: =SUMIF('Production '!$C$4:$AI$4407,'Tracking Sheet'!B10,'Production '!$AG$4:$AG$4407) -> 0
B11: ='Production '!C14 -> 46594 | C11: =SUMIF('Production '!$C$4:$AI$4407,'Tracking Sheet'!B11,'Production '!$M$4:$M$4407) -> 9435 | D11: =SUMIF('Production '!$C$4:$AI$4407,'Tracking Sheet'!B11,'Production '!$Q$4:$Q$4407) -> 0 | E11: =SUMIF('Production '!$C$4:$AI$4407,'Tracking Sheet'!B11,'Production '!$S$4:$S$4407) -> 0 | F11: =SUMIF('Production '!$C$4:$AI$4407,'Tracking Sheet'!B11,'Production '!$U$4:$U$4407) -> 67 | G11: =SUMIF('Production '!$C$4:$AI$4407,'Tracking Sheet'!B11,'Production '!$W$4:$W$4407) -> 9368 | H11: =SUMIF('Production '!$C$4:$AI$4407,'Tracking Sheet'!B11,'Production '!$F$4:$F$4407) -> 9122 | I11: =SUMIF('Production '!$C$4:$AI$4407,'Tracking Sheet'!B11,'Production '!$V$4:$V$4407) -> 0 | J11: =SUMIF('Production '!$C$4:$AI$4407,'Tracking Sheet'!B11,'Production '!$AG$4:$AG$4407) -> 0
B12: ='Production '!C15 -> 46594 | C12: =SUMIF('Production '!$C$4:$AI$4407,'Tracking Sheet'!B12,'Production '!$M$4:$M$4407) -> 9435 | D12: =SUMIF('Production '!$C$4:$AI$4407,'Tracking Sheet'!B12,'Production '!$Q$4:$Q$4407) -> 0 | E12: =SUMIF('Production '!$C$4:$AI$4407,'Tracking Sheet'!B12,'Production '!$S$4:$S$4407) -> 0 | F12: =SUMIF('Production '!$C$4:$AI$4407,'Tracking Sheet'!B12,'Production '!$U$4:$U$4407) -> 67 | G12: =SUMIF('Production '!$C$4:$AI$4407,'Tracking Sheet'!B12,'Production '!$W$4:$W$4407) -> 9368 | H12: =SUMIF('Production '!$C$4:$AI$4407,'Tracking Sheet'!B12,'Production '!$F$4:$F$4407) -> 9122 | I12: =SUMIF('Production '!$C$4:$AI$4407,'Tracking Sheet'!B12,'Production '!$V$4:$V$4407) -> 0 | J12: =SUMIF('Production '!$C$4:$AI$4407,'Tracking Sheet'!B12,'Production '!$AG$4:$AG$4407) -> 0
B13: ='Production '!C16 -> 0 | C13: =SUMIF('Production '!$C$4:$AI$4407,'Tracking Sheet'!B13,'Production '!$M$4:$M$4407) -> #DIV/0! | D13: =SUMIF('Production '!$C$4:$AI$4407,'Tracking Sheet'!B13,'Production '!$Q$4:$Q$4407) -> #DIV/0! | E13: =SUMIF('Production '!$C$4:$AI$4407,'Tracking Sheet'!B13,'Production '!$S$4:$S$4407) -> -1268219 | F13: =SUMIF('Production '!$C$4:$AI$4407,'Tracking Sheet'!B13,'Production '!$U$4:$U$4407) -> -10620.436 | G13: =SUMIF('Production '!$C$4:$AI$4407,'Tracking Sheet'!B13,'Production '!$W$4:$W$4407) -> #DIV/0! | H13: =SUMIF('Production '!$C$4:$AI$4407,'Tracking Sheet'!B13,'Production '!$F$4:$F$4407) -> 3230621.3 | I13: =SUMIF('Production '!$C$4:$AI$4407,'Tracking Sheet'!B13,'Production '!$V$4:$V$4407) -> -489.86488 | J13: =SUMIF('Production '!$C$4:$AI$4407,'Tracking Sheet'!B13,'Production '!$AG$4:$AG$4407) -> 0
B14: ='Production '!C17 -> 0 | C14: =SUMIF('Production '!$C$4:$AI$4407,'Tracking Sheet'!B14,'Production '!$M$4:$M$4407) -> #DIV/0! | D14: =SUMIF('Production '!$C$4:$AI$4407,'Tracking Sheet'!B14,'Production '!$Q$4:$Q$4407) -> #DIV/0! | E14: =SUMIF('Production '!$C$4:$AI$4407,'Tracking Sheet'!B14,'Production '!$S$4:$S$4407) -> -1268219 | F14: =SUMIF('Production '!$C$4:$AI$4407,'Tracking Sheet'!B14,'Production '!$U$4:$U$4407) -> -10620.436 | G14: =SUMIF('Production '!$C$4:$AI$4407,'Tracking Sheet'!B14,'Production '!$W$4:$W$4407) -> #DIV/0! | H14: =SUMIF('Production '!$C$4:$AI$4407,'Tracking Sheet'!B14,'Production '!$F$4:$F$4407) -> 3230621.3 | I14: =SUMIF('Production '!$C$4:$AI$4407,'Tracking Sheet'!B14,'Production '!$V$4:$V$4407) -> -489.86488 | J14: =SUMIF('Production '!$C$4:$AI$4407,'Tracking Sheet'!B14,'Production '!$AG$4:$AG$4407) -> 0
... B3255: ='Production '!C3258 -> 0 | C3255: =SUMIF('Production '!$C$4:$AI$4407,'Tracking Sheet'!B3255,'Production '!$M$4:$M$4407) -> #DIV/0! | D3255: =SUMIF('Production '!$C$4:$AI$4407,'Tracking Sheet'!B3255,'Production '!$Q$4:$Q$4407) -> #DIV/0! | E3255: =SUMIF('Production '!$C$4:$AI$4407,'Tracking Sheet'!B3255,'Production '!$S$4:$S$4407) -> -1268219 | F3255: =SUMIF('Production '!$C$4:$AI$4407,'Tracking Sheet'!B3255,'Production '!$U$4:$U$4407) -> -10620.436 | G3255: =SUMIF('Production '!$C$4:$AI$4407,'Tracking Sheet'!B3255,'Production '!$W$4:$W$4407) -> #DIV/0! | H3255: =SUMIF('Production '!$C$4:$AI$4407,'Tracking Sheet'!B3255,'Production '!$F$4:$F$4407) -> 3230621.3 | I3255: =SUMIF('Production '!$C$4:$AI$4407,'Tracking Sheet'!B3255,'Production '!$V$4:$V$4407) -> -489.86488 | J3255: =SUMIF('Production '!$C$4:$AI$4407,'Tracking Sheet'!B3255,'Production '!$AG$4:$AG$4407) -> 0
